<mujoco model="base">
  <compiler angle="radian" meshdir="meshes/" inertiagrouprange="0 0" />
  <option impratio="20" cone="elliptic" density="1.2" viscosity="0.00002" timestep="0.002" />
  <size nconmax="5000" njmax="5000" />

  <asset>
  <texture builtin="gradient" height="256" rgb1=".9 .9 1." rgb2=".2 .3 .4" type="skybox" width="256" />
    <texture file="/home/wireless/miniconda3/envs/th_torch/lib/python3.10/site-packages/robosuite/models/assets/arenas/../textures/light-gray-floor-tile.png" type="2d" name="texplane" />
    <material name="floorplane" reflectance="0.01" shininess="0.0" specular="0.0" texrepeat="2 2" texture="texplane" texuniform="true" />
    
    <texture file="/home/wireless/miniconda3/envs/th_torch/lib/python3.10/site-packages/robosuite/models/assets/arenas/../textures/ceramic.png" type="cube" name="tex-ceramic" />
    <material name="table_ceramic" reflectance="0.0" shininess="0.0" specular="0.2" texrepeat="1 1" texture="tex-ceramic" />
    
    <texture file="/home/wireless/miniconda3/envs/th_torch/lib/python3.10/site-packages/robosuite/models/assets/arenas/../textures/steel-brushed.png" type="cube" name="tex-steel-brushed" />
    <material name="table_legs_metal" reflectance="0.8" shininess="0.8" texrepeat="1 1" texture="tex-steel-brushed" />
    
    <texture file="/home/wireless/miniconda3/envs/th_torch/lib/python3.10/site-packages/robosuite/models/assets/arenas/../textures/light-gray-plaster.png" type="2d" name="tex-light-gray-plaster" />
    <material name="walls_mat" reflectance="0.0" shininess="0.1" specular="0.1" texrepeat="3 3" texture="tex-light-gray-plaster" texuniform="true" />
    
    <texture name="textable" builtin="flat" height="512" width="512" rgb1="0.5 0.5 0.5" rgb2="0.5 0.5 0.5" />
    <material name="table_mat" texture="textable" />

  </asset>

  <visual>
    <map znear="0.001" />
  </visual>

  <actuator>
  <position kv="500" name="1_actuator_joint" joint="robot1_vertical_joint" /><position kp="10000" kv="600" name="1_actuator_joint2" joint="robot1_vertical_joint2" /><position kv="500" name="2_actuator_joint" joint="robot2_vertical_joint" /><position kp="10000" kv="600" name="2_actuator_joint2" joint="robot2_vertical_joint2" /><position kv="500" name="3_actuator_joint" joint="robot3_vertical_joint" /><position kp="10000" kv="600" name="3_actuator_joint2" joint="robot3_vertical_joint2" /><position kv="500" name="4_actuator_joint" joint="robot4_vertical_joint" /><position kp="10000" kv="600" name="4_actuator_joint2" joint="robot4_vertical_joint2" /></actuator>

  <worldbody>
  <geom condim="3" group="1" material="floorplane" name="floor" pos="0.0 0.0 0.0" size="3 3 .125" type="plane" />
    
    <geom pos="-1.25 2.25 1.5" quat="0.6532815 0.6532815 0.2705981 0.2705981" size="1.06 1.5 0.01" type="box" conaffinity="0" contype="0" group="1" name="wall_leftcorner_visual" material="walls_mat" />
    <geom pos="-1.25 -2.25 1.5" quat="0.6532815 0.6532815 -0.2705981 -0.2705981" size="1.06 1.5 0.01" type="box" conaffinity="0" contype="0" group="1" name="wall_rightcorner_visual" material="walls_mat" />
    <geom pos="1.25 3 1.5" quat="0.7071 0.7071 0 0" size="1.75 1.5 0.01" type="box" conaffinity="0" contype="0" group="1" name="wall_left_visual" material="walls_mat" />
    <geom pos="1.25 -3 1.5" quat="0.7071 -0.7071 0 0" size="1.75 1.5 0.01" type="box" conaffinity="0" contype="0" group="1" name="wall_right_visual" material="walls_mat" />
    <geom pos="-2 0 1.5" quat="0.5 0.5 0.5 0.5" size="1.5 1.5 0.01" type="box" conaffinity="0" contype="0" group="1" name="wall_rear_visual" material="walls_mat" />
    <geom pos="3 0 1.5" quat="0.5 0.5 -0.5 -0.5" size="3 1.5 0.01" type="box" conaffinity="0" contype="0" group="1" name="wall_front_visual" material="walls_mat" />
    
    <body name="table" pos="-1.0 0.0 0.07500000000000001">
      <geom pos="0 0 0" size="0.5 0.5 0.025" type="box" group="0" name="table_collision" friction="1 0.005 0.0001" rgba="0.5 0.5 0 1" />
      <geom pos="0 0 0" size="0.5 0.5 0.025" type="box" conaffinity="0" contype="0" group="1" name="table_visual" material="table_ceramic" />
      <site pos="0.0 0.0 0.025" name="table_top" size="0.001 0.001 0.001" rgba="0 0 0 0" />
      
      <geom pos="0 0 0" size="0.0001 0.0001" type="cylinder" conaffinity="0" contype="0" group="1" name="table_leg1_visual" material="table_legs_metal" rgba="1 0 0 0" />
      <geom pos="0 0 0" size="0.0001 0.0001" type="cylinder" conaffinity="0" contype="0" group="1" name="table_leg2_visual" material="table_legs_metal" rgba="1 0 0 0" />
      <geom pos="0 0 0" size="0.0001 0.0001" type="cylinder" conaffinity="0" contype="0" group="1" name="table_leg3_visual" material="table_legs_metal" rgba="1 0 0 0" />
      <geom pos="0 0 0" size="0.0001 0.0001" type="cylinder" conaffinity="0" contype="0" group="1" name="table_leg4_visual" material="table_legs_metal" rgba="1 0 0 0" />
    </body>
    <light pos="1.0 1.0 1.5" dir="-0.2 -0.2 -1" specular="0.3 0.3 0.3" directional="true" castshadow="false" />
    
    <camera mode="fixed" name="frontview" pos="1.6 0 1.45" quat="0.56 0.43 0.43 0.56" />
    
    <camera mode="fixed" name="birdview" pos="-0.2 0 3.0" quat="0.7071 0 0 0.7071" />
    
    <camera mode="fixed" name="agentview" pos="0.5 0 1.35" quat="0.653 0.271 0.271 0.653" />
    
    <camera mode="fixed" name="sideview" pos="-0.05651774593317116 1.2761224129427358 1.4879572214102434" quat="0.009905065491771751 0.006877963156909582 0.5912228352893879 0.806418094001364" />

  <body name="robot1" pos="-0.7 0.3 0.1" quat="-0.3827 0 0 0.9239"><body name="robot1_link1" pos="0 0 0"><joint type="slide" axis="0 0 1" pos="0 0 0" range="0 2" name="robot1_vertical_joint" /><geom name="robot1_link1_geom" type="capsule" size="0.05 0.2" pos="0 0 0.1" rgba="1 1 0 1" contype="1" conaffinity="1" /><body name="robot1_link2" pos="0 0 0.5"><joint type="slide" axis="0 0 1" pos="0 0 0" range="0 2" armature="0.01" stiffness="2000" damping="5" name="robot1_vertical_joint2" /><geom name="robot1_link2_geom" type="cylinder" size="0.05 0.4" pos="0 0 0.2" contype="1" conaffinity="1" /><body name="robot1_end_effector" pos="0 0 0.5"><geom name="robot1_ee_geom" type="sphere" size="0.05" pos="0 0 0.1" /><site name="ee_force_site1" type="sphere" pos="0 0 0.1" size="0.05" rgba="0 0 1 1" /></body></body><body name="robot1_guide" pos="0 0 0"><geom name="robot1_guide_geom" type="cylinder" size="0.025 0.9" pos="0 0 0.4" /></body></body></body><body name="robot2" pos="-1.3 0.3 0.1" quat="-0.9239 0 0 0.3827"><body name="robot2_link1" pos="0 0 0"><joint type="slide" axis="0 0 1" pos="0 0 0" range="0 2" name="robot2_vertical_joint" /><geom name="robot2_link1_geom" type="capsule" size="0.05 0.2" pos="0 0 0.1" rgba="1 1 0 1" contype="1" conaffinity="1" /><body name="robot2_link2" pos="0 0 0.5"><joint type="slide" axis="0 0 1" pos="0 0 0" range="0 2" armature="0.01" stiffness="2000" damping="5" name="robot2_vertical_joint2" /><geom name="robot2_link2_geom" type="cylinder" size="0.05 0.4" pos="0 0 0.2" contype="1" conaffinity="1" /><body name="robot2_end_effector" pos="0 0 0.5"><geom name="robot2_ee_geom" type="sphere" size="0.05" pos="0 0 0.1" /><site name="ee_force_site2" type="sphere" pos="0 0 0.1" size="0.05" rgba="0 0 1 1" /></body></body><body name="robot2_guide" pos="0 0 0"><geom name="robot2_guide_geom" type="cylinder" size="0.025 0.9" pos="0 0 0.4" /></body></body></body><body name="robot3" pos="-0.7 -0.3 0.1" quat="0.3827 0 0 0.9239"><body name="robot3_link1" pos="0 0 0"><joint type="slide" axis="0 0 1" pos="0 0 0" range="0 2" name="robot3_vertical_joint" /><geom name="robot3_link1_geom" type="capsule" size="0.05 0.2" pos="0 0 0.1" rgba="1 1 0 1" contype="1" conaffinity="1" /><body name="robot3_link2" pos="0 0 0.5"><joint type="slide" axis="0 0 1" pos="0 0 0" range="0 2" armature="0.01" stiffness="2000" damping="5" name="robot3_vertical_joint2" /><geom name="robot3_link2_geom" type="cylinder" size="0.05 0.4" pos="0 0 0.2" contype="1" conaffinity="1" /><body name="robot3_end_effector" pos="0 0 0.5"><geom name="robot3_ee_geom" type="sphere" size="0.05" pos="0 0 0.1" /><site name="ee_force_site3" type="sphere" pos="0 0 0.1" size="0.05" rgba="0 0 1 1" /></body></body><body name="robot3_guide" pos="0 0 0"><geom name="robot3_guide_geom" type="cylinder" size="0.025 0.9" pos="0 0 0.4" /></body></body></body><body name="robot4" pos="-1.3 -0.3 0.1" quat="0.9239 0 0 0.3827"><body name="robot4_link1" pos="0 0 0"><joint type="slide" axis="0 0 1" pos="0 0 0" range="0 2" name="robot4_vertical_joint" /><geom name="robot4_link1_geom" type="capsule" size="0.05 0.2" pos="0 0 0.1" rgba="1 1 0 1" contype="1" conaffinity="1" /><body name="robot4_link2" pos="0 0 0.5"><joint type="slide" axis="0 0 1" pos="0 0 0" range="0 2" armature="0.01" stiffness="2000" damping="5" name="robot4_vertical_joint2" /><geom name="robot4_link2_geom" type="cylinder" size="0.05 0.4" pos="0 0 0.2" contype="1" conaffinity="1" /><body name="robot4_end_effector" pos="0 0 0.5"><geom name="robot4_ee_geom" type="sphere" size="0.05" pos="0 0 0.1" /><site name="ee_force_site4" type="sphere" pos="0 0 0.1" size="0.05" rgba="0 0 1 1" /></body></body><body name="robot4_guide" pos="0 0 0"><geom name="robot4_guide_geom" type="cylinder" size="0.025 0.9" pos="0 0 0.4" /></body></body></body><body pos="-1 0 2" name="box_main"><geom rgba="0.5 0 0 1" density="1000" friction="1 0.005 0.0001" solref="0.02 1.0" solimp="0.9 0.95 0.001" type="box" size="0.6 0.6 0.1" pos="0 0 0" group="0" name="box_g0" /><geom conaffinity="0" contype="0" mass="1e-8" rgba="1 0 0 1" type="box" size="0.6 0.6 0.1" pos="0 0 0" group="1" name="box_g0_vis" /><joint type="free" name="box_joint0" /><site type="sphere" group="0" pos="0 0 0" size="0.002 0.002 0.002" rgba="1 0 0 1" name="box_default_site" /></body><camera name="overview" pos="0 0 3" mode="fixed" quat="0.3827 0 0 0.9239" fovy="45" /></worldbody>

  <equality>
  </equality>
<sensor><force name="force_sensor1" site="ee_force_site1" /><force name="force_sensor2" site="ee_force_site2" /><force name="force_sensor3" site="ee_force_site3" /><force name="force_sensor4" site="ee_force_site4" /></sensor><tendon /><contact><pair geom1="robot1_link1_geom" geom2="robot1_link2_geom" /><pair geom1="robot2_link1_geom" geom2="robot2_link2_geom" /><pair geom1="robot3_link1_geom" geom2="robot3_link2_geom" /><pair geom1="robot4_link1_geom" geom2="robot4_link2_geom" /></contact></mujoco>